<?xml version="1.0" ?>
<robot name="isro" xmlns:xacro="http://www.ros.org/wiki/xacro">

<xacro:include filename="$(find isro_description)/urdf/materials.xacro" />
<xacro:include filename="$(find isro_description)/urdf/isro.trans" />
<xacro:include filename="$(find isro_description)/urdf/isro.gazebo" />

<!-- Define the world link -->
<link name="base_footprint"/>

<!-- Connect world link to the robot base link -->
<joint name="base_footprint_joint" type="fixed">
  <origin xyz="0 0 0" rpy="0 0 0"/>
  <parent link="base_footprint"/>
  <child link="base_link"/>
</joint>


<link name="base_link">
  <inertial>
    <origin xyz="0.04777866183877663 0.0014554936488563105 0.2654648191746249" rpy="0 0 0"/>
    <mass value="0.5"/>
    <inertia ixx="0.400695" iyy="0.310868" izz="0.529139" ixy="0.000286" iyz="-0.001803" ixz="-0.006282"/>
  </inertial>
  <visual>
    <origin xyz="0 0 0" rpy="0 0 0"/>
    <geometry>
      <mesh filename="package://isro_description/meshes/base_link.stl" scale="0.001 0.001 0.001"/>
    </geometry>
    <material name="black"/>
  </visual>
  <collision>
    <origin xyz="0 0 0" rpy="0 0 0"/>
    <geometry>
      <mesh filename="package://isro_description/meshes/base_link.stl" scale="0.001 0.001 0.001"/>
    </geometry>
  </collision>
</link>

<link name="left_wheel_1_1">
  <inertial>
    <origin xyz="-0.0007825205386265965 0.08085195131234404 -0.02164488479609475" rpy="0 0 0"/>
    <mass value="0.2"/>
    <inertia ixx="2.9e-05" iyy="2.9e-05" izz="1e-06" ixy="-0.0" iyz="0.0" ixz="0.0"/>
  </inertial>
  <visual>
    <origin xyz="-0.324728 -0.222336 -0.119819" rpy="0 0 0"/>
    <geometry>
      <mesh filename="package://isro_description/meshes/left_wheel_1_1.stl" scale="0.001 0.001 0.001"/>
    </geometry>
    <material name="red"/>
  </visual>
  <collision>
    <origin xyz="-0.324728 -0.222336 -0.119819" rpy="0 0 0"/>
    <geometry>
      <mesh filename="package://isro_description/meshes/left_wheel_1_1.stl" scale="0.001 0.001 0.001"/>
    </geometry>
  </collision>
</link>

<link name="left_wheel_2_1">
  <inertial>
    <origin xyz="-0.0007823709985341808 0.08085157824233241 -0.021644700512749" rpy="0 0 0"/>
    <mass value="0.2"/>
    <inertia ixx="2.9e-05" iyy="2.9e-05" izz="1e-06" ixy="-0.0" iyz="0.0" ixz="0.0"/>
  </inertial>
  <visual>
    <origin xyz="0.005474 -0.219285 -0.120169" rpy="0 0 0"/>
    <geometry>
      <mesh filename="package://isro_description/meshes/left_wheel_2_1.stl" scale="0.001 0.001 0.001"/>
    </geometry>
    <material name="red"/>
  </visual>
  <collision>
    <origin xyz="0.005474 -0.219285 -0.120169" rpy="0 0 0"/>
    <geometry>
      <mesh filename="package://isro_description/meshes/left_wheel_2_1.stl" scale="0.001 0.001 0.001"/>
    </geometry>
  </collision>
</link>

<link name="left_wheel_3_1">
  <inertial>
    <origin xyz="-0.000782185724829354 0.08085120674738841 -0.021644718269895183" rpy="0 0 0"/>
    <mass value="0.2"/>
    <inertia ixx="2.9e-05" iyy="2.9e-05" izz="1e-06" ixy="-0.0" iyz="0.0" ixz="0.0"/>
  </inertial>
  <visual>
    <origin xyz="0.327831 -0.203815 -0.116933" rpy="0 0 0"/>
    <geometry>
      <mesh filename="package://isro_description/meshes/left_wheel_3_1.stl" scale="0.001 0.001 0.001"/>
    </geometry>
    <material name="red"/>
  </visual>
  <collision>
    <origin xyz="0.327831 -0.203815 -0.116933" rpy="0 0 0"/>
    <geometry>
      <mesh filename="package://isro_description/meshes/left_wheel_3_1.stl" scale="0.001 0.001 0.001"/>
    </geometry>
  </collision>
</link>

<link name="right_wheel_1_1">
  <inertial>
    <origin xyz="0.0007094488332242688 -0.08085195898693015 0.02164511230635062" rpy="0 0 0"/>
    <mass value="0.2"/>
    <inertia ixx="2.9e-05" iyy="2.9e-05" izz="1e-06" ixy="0.0" iyz="0.0" ixz="-0.0"/>
  </inertial>
  <visual>
    <origin xyz="-0.328756 0.213644 -0.118712" rpy="0 0 0"/>
    <geometry>
      <mesh filename="package://isro_description/meshes/right_wheel_1_1.stl" scale="0.001 0.001 0.001"/>
    </geometry>
    <material name="red"/>
  </visual>
  <collision>
    <origin xyz="-0.328756 0.213644 -0.118712" rpy="0 0 0"/>
    <geometry>
      <mesh filename="package://isro_description/meshes/right_wheel_1_1.stl" scale="0.001 0.001 0.001"/>
    </geometry>
  </collision>
</link>

<link name="right_wheel_2_1">
  <inertial>
    <origin xyz="0.0007095983733356598 -0.08085233205873135 0.02164529658974282" rpy="0 0 0"/>
    <mass value="0.2"/>
    <inertia ixx="2.9e-05" iyy="2.9e-05" izz="1e-06" ixy="0.0" iyz="0.0" ixz="-0.0"/>
  </inertial>
  <visual>
    <origin xyz="0.001446 0.216695 -0.119062" rpy="0 0 0"/>
    <geometry>
      <mesh filename="package://isro_description/meshes/right_wheel_2_1.stl" scale="0.001 0.001 0.001"/>
    </geometry>
    <material name="red"/>
  </visual>
  <collision>
    <origin xyz="0.001446 0.216695 -0.119062" rpy="0 0 0"/>
    <geometry>
      <mesh filename="package://isro_description/meshes/right_wheel_2_1.stl" scale="0.001 0.001 0.001"/>
    </geometry>
  </collision>
</link>

<link name="right_wheel_3_1">
  <inertial>
    <origin xyz="0.0007098382116191293 -0.08085185079248342 0.02164471968615435" rpy="0 0 0"/>
    <mass value="0.2"/>
    <inertia ixx="2.9e-05" iyy="2.9e-05" izz="1e-06" ixy="0.0" iyz="0.0" ixz="-0.0"/>
  </inertial>
  <visual>
    <origin xyz="0.324034 0.207167 -0.11589" rpy="0 0 0"/>
    <geometry>
      <mesh filename="package://isro_description/meshes/right_wheel_3_1.stl" scale="0.001 0.001 0.001"/>
    </geometry>
    <material name="red"/>
  </visual>
  <collision>
    <origin xyz="0.324034 0.207167 -0.11589" rpy="0 0 0"/>
    <geometry>
      <mesh filename="package://isro_description/meshes/right_wheel_3_1.stl" scale="0.001 0.001 0.001"/>
    </geometry>
  </collision>
</link>

<link name="lidar_1_1">
  <inertial>
    <origin xyz="0.00010497148756166697 2.6756896755608314e-05 -0.009999223277012914" rpy="0 0 0"/>
    <mass value="0.1"/>
    <inertia ixx="5e-05" iyy="5e-05" izz="8.2e-05" ixy="0.0" iyz="-0.0" ixz="-0.0"/>
  </inertial>
  <visual>
    <origin xyz="-0.276183 -0.003494 -0.270917" rpy="0 0 0"/>
    <geometry>
      <mesh filename="package://isro_description/meshes/lidar_1_1.stl" scale="0.001 0.001 0.001"/>
    </geometry>
    <material name="white"/>
  </visual>
  <collision>
    <origin xyz="-0.276183 -0.003494 -0.270917" rpy="0 0 0"/>
    <geometry>
      <mesh filename="package://isro_description/meshes/lidar_1_1.stl" scale="0.001 0.001 0.001"/>
    </geometry>
  </collision>
</link>

<joint name="Revolute_1" type="continuous">
  <origin xyz="0.324728 0.222336 0.119819" rpy="0 0 0"/>
  <parent link="base_link"/>
  <child link="left_wheel_1_1"/>
  <axis xyz="0.0 1.0 0.0"/>
</joint>

<joint name="Revolute_2" type="continuous">
  <origin xyz="-0.005474 0.219285 0.120169" rpy="0 0 0"/>
  <parent link="base_link"/>
  <child link="left_wheel_2_1"/>
  <axis xyz="0.0 1.0 0.0"/>
</joint>

<joint name="Revolute_3" type="continuous">
  <origin xyz="-0.327831 0.203815 0.116933" rpy="0 0 0"/>
  <parent link="base_link"/>
  <child link="left_wheel_3_1"/>
  <axis xyz="0.0 1.0 0.0"/>
</joint>

<joint name="Revolute_4" type="continuous">
  <origin xyz="0.328756 -0.213644 0.118712" rpy="0 0 0"/>
  <parent link="base_link"/>
  <child link="right_wheel_1_1"/>
  <axis xyz="0.0 1.0 0.0"/>
</joint>

<joint name="Revolute_5" type="continuous">
  <origin xyz="-0.001446 -0.216695 0.119062" rpy="0 0 0"/>
  <parent link="base_link"/>
  <child link="right_wheel_2_1"/>
  <axis xyz="0.0 1.0 0.0"/>
</joint>

<joint name="Revolute_6" type="continuous">
  <origin xyz="-0.324034 -0.207167 0.11589" rpy="0 0 0"/>
  <parent link="base_link"/>
  <child link="right_wheel_3_1"/>
  <axis xyz="0.0 1.0 0.0"/>
</joint>

<joint name="Rigid_1" type="fixed">
  <origin xyz="0.276183 0.003494 0.270917" rpy="0 0 0"/>
  <parent link="base_link"/>
  <child link="lidar_1_1"/>
</joint>

</robot>
